Details of error at 2019-02-18 19:44:
 
Traceback (most recent call last):
  File "/Users/ivanwahlrab/Documents/Semester_2_19/Software_Engineering_30830/Project/dublinBikes/softwareEngineering/dublinBikes/staticDataScraper.py", line 68, in <module>
    for row in dbds:
NameError: name 'dbds' is not defined

Details of error at 2019-02-18 19:46:
 
Traceback (most recent call last):
  File "/Users/ivanwahlrab/Documents/Semester_2_19/Software_Engineering_30830/Project/dublinBikes/softwareEngineering/dublinBikes/staticDataScraper.py", line 68, in <module>
    for row in dbds:
NameError: name 'dbds' is not defined

Details of error at 2019-02-18 19:46:
 
Traceback (most recent call last):
  File "/Users/ivanwahlrab/Documents/Semester_2_19/Software_Engineering_30830/Project/dublinBikes/softwareEngineering/dublinBikes/staticDataScraper.py", line 68, in <module>
    for row in dbds:
NameError: name 'dbds' is not defined

Details of error at 2019-02-18 19:52:
 
Traceback (most recent call last):
  File "/Users/ivanwahlrab/Documents/Semester_2_19/Software_Engineering_30830/Project/dublinBikes/softwareEngineering/dublinBikes/staticDataScraper.py", line 70, in <module>
    writeData(bikesSQL)
  File "/Users/ivanwahlrab/Documents/Semester_2_19/Software_Engineering_30830/Project/dublinBikes/softwareEngineering/dublinBikes/staticDataScraper.py", line 61, in writeData
    cursorObject.execute(query)
  File "/Users/ivanwahlrab/anaconda3/lib/python3.6/site-packages/pymysql/cursors.py", line 170, in execute
    result = self._query(query)
  File "/Users/ivanwahlrab/anaconda3/lib/python3.6/site-packages/pymysql/cursors.py", line 328, in _query
    conn.query(q)
  File "/Users/ivanwahlrab/anaconda3/lib/python3.6/site-packages/pymysql/connections.py", line 517, in query
    self._affected_rows = self._read_query_result(unbuffered=unbuffered)
  File "/Users/ivanwahlrab/anaconda3/lib/python3.6/site-packages/pymysql/connections.py", line 732, in _read_query_result
    result.read()
  File "/Users/ivanwahlrab/anaconda3/lib/python3.6/site-packages/pymysql/connections.py", line 1075, in read
    first_packet = self.connection._read_packet()
  File "/Users/ivanwahlrab/anaconda3/lib/python3.6/site-packages/pymysql/connections.py", line 684, in _read_packet
    packet.check_error()
  File "/Users/ivanwahlrab/anaconda3/lib/python3.6/site-packages/pymysql/protocol.py", line 220, in check_error
    err.raise_mysql_exception(self._data)
  File "/Users/ivanwahlrab/anaconda3/lib/python3.6/site-packages/pymysql/err.py", line 109, in raise_mysql_exception
    raise errorclass(errno, errval)
pymysql.err.IntegrityError: (1062, "Duplicate entry 'SMITHFIELD NORTH' for key 'PRIMARY'")

Details of error at 2019-02-18 19:53:
 
Traceback (most recent call last):
  File "/Users/ivanwahlrab/Documents/Semester_2_19/Software_Engineering_30830/Project/dublinBikes/softwareEngineering/dublinBikes/staticDataScraper.py", line 70, in <module>
    writeData(bikesSQL)
  File "/Users/ivanwahlrab/Documents/Semester_2_19/Software_Engineering_30830/Project/dublinBikes/softwareEngineering/dublinBikes/staticDataScraper.py", line 61, in writeData
    cursorObject.execute(query)
  File "/Users/ivanwahlrab/anaconda3/lib/python3.6/site-packages/pymysql/cursors.py", line 170, in execute
    result = self._query(query)
  File "/Users/ivanwahlrab/anaconda3/lib/python3.6/site-packages/pymysql/cursors.py", line 328, in _query
    conn.query(q)
  File "/Users/ivanwahlrab/anaconda3/lib/python3.6/site-packages/pymysql/connections.py", line 517, in query
    self._affected_rows = self._read_query_result(unbuffered=unbuffered)
  File "/Users/ivanwahlrab/anaconda3/lib/python3.6/site-packages/pymysql/connections.py", line 732, in _read_query_result
    result.read()
  File "/Users/ivanwahlrab/anaconda3/lib/python3.6/site-packages/pymysql/connections.py", line 1075, in read
    first_packet = self.connection._read_packet()
  File "/Users/ivanwahlrab/anaconda3/lib/python3.6/site-packages/pymysql/connections.py", line 684, in _read_packet
    packet.check_error()
  File "/Users/ivanwahlrab/anaconda3/lib/python3.6/site-packages/pymysql/protocol.py", line 220, in check_error
    err.raise_mysql_exception(self._data)
  File "/Users/ivanwahlrab/anaconda3/lib/python3.6/site-packages/pymysql/err.py", line 109, in raise_mysql_exception
    raise errorclass(errno, errval)
pymysql.err.IntegrityError: (1062, "Duplicate entry 'SMITHFIELD NORTH' for key 'PRIMARY'")

Details of error at 2019-02-18 20:11:
 
Traceback (most recent call last):
  File "/Users/ivanwahlrab/Documents/Semester_2_19/Software_Engineering_30830/Project/dublinBikes/softwareEngineering/dublinBikes/staticDataScraper.py", line 71, in <module>
    writeData(bikesSQL)
  File "/Users/ivanwahlrab/Documents/Semester_2_19/Software_Engineering_30830/Project/dublinBikes/softwareEngineering/dublinBikes/staticDataScraper.py", line 62, in writeData
    cursorObject.execute(query)
  File "/Users/ivanwahlrab/anaconda3/lib/python3.6/site-packages/pymysql/cursors.py", line 170, in execute
    result = self._query(query)
  File "/Users/ivanwahlrab/anaconda3/lib/python3.6/site-packages/pymysql/cursors.py", line 328, in _query
    conn.query(q)
  File "/Users/ivanwahlrab/anaconda3/lib/python3.6/site-packages/pymysql/connections.py", line 517, in query
    self._affected_rows = self._read_query_result(unbuffered=unbuffered)
  File "/Users/ivanwahlrab/anaconda3/lib/python3.6/site-packages/pymysql/connections.py", line 732, in _read_query_result
    result.read()
  File "/Users/ivanwahlrab/anaconda3/lib/python3.6/site-packages/pymysql/connections.py", line 1075, in read
    first_packet = self.connection._read_packet()
  File "/Users/ivanwahlrab/anaconda3/lib/python3.6/site-packages/pymysql/connections.py", line 684, in _read_packet
    packet.check_error()
  File "/Users/ivanwahlrab/anaconda3/lib/python3.6/site-packages/pymysql/protocol.py", line 220, in check_error
    err.raise_mysql_exception(self._data)
  File "/Users/ivanwahlrab/anaconda3/lib/python3.6/site-packages/pymysql/err.py", line 109, in raise_mysql_exception
    raise errorclass(errno, errval)
pymysql.err.IntegrityError: (1062, "Duplicate entry 'SMITHFIELD NORTH' for key 'PRIMARY'")

Details of error at 2019-02-18 20:13:
 
Traceback (most recent call last):
  File "/Users/ivanwahlrab/Documents/Semester_2_19/Software_Engineering_30830/Project/dublinBikes/softwareEngineering/dublinBikes/staticDataScraper.py", line 71, in <module>
    writeData(bikesSQL)
  File "/Users/ivanwahlrab/Documents/Semester_2_19/Software_Engineering_30830/Project/dublinBikes/softwareEngineering/dublinBikes/staticDataScraper.py", line 62, in writeData
    cursorObject.execute(query)
  File "/Users/ivanwahlrab/anaconda3/lib/python3.6/site-packages/pymysql/cursors.py", line 170, in execute
    result = self._query(query)
  File "/Users/ivanwahlrab/anaconda3/lib/python3.6/site-packages/pymysql/cursors.py", line 328, in _query
    conn.query(q)
  File "/Users/ivanwahlrab/anaconda3/lib/python3.6/site-packages/pymysql/connections.py", line 517, in query
    self._affected_rows = self._read_query_result(unbuffered=unbuffered)
  File "/Users/ivanwahlrab/anaconda3/lib/python3.6/site-packages/pymysql/connections.py", line 732, in _read_query_result
    result.read()
  File "/Users/ivanwahlrab/anaconda3/lib/python3.6/site-packages/pymysql/connections.py", line 1075, in read
    first_packet = self.connection._read_packet()
  File "/Users/ivanwahlrab/anaconda3/lib/python3.6/site-packages/pymysql/connections.py", line 684, in _read_packet
    packet.check_error()
  File "/Users/ivanwahlrab/anaconda3/lib/python3.6/site-packages/pymysql/protocol.py", line 220, in check_error
    err.raise_mysql_exception(self._data)
  File "/Users/ivanwahlrab/anaconda3/lib/python3.6/site-packages/pymysql/err.py", line 109, in raise_mysql_exception
    raise errorclass(errno, errval)
pymysql.err.IntegrityError: (1062, "Duplicate entry 'SMITHFIELD NORTH' for key 'PRIMARY'")

Details of error at 2019-02-18 20:13:
 
Traceback (most recent call last):
  File "/Users/ivanwahlrab/Documents/Semester_2_19/Software_Engineering_30830/Project/dublinBikes/softwareEngineering/dublinBikes/staticDataScraper.py", line 72, in <module>
    writeData(bikesSQL)
  File "/Users/ivanwahlrab/Documents/Semester_2_19/Software_Engineering_30830/Project/dublinBikes/softwareEngineering/dublinBikes/staticDataScraper.py", line 62, in writeData
    cursorObject.execute(query)
  File "/Users/ivanwahlrab/anaconda3/lib/python3.6/site-packages/pymysql/cursors.py", line 170, in execute
    result = self._query(query)
  File "/Users/ivanwahlrab/anaconda3/lib/python3.6/site-packages/pymysql/cursors.py", line 328, in _query
    conn.query(q)
  File "/Users/ivanwahlrab/anaconda3/lib/python3.6/site-packages/pymysql/connections.py", line 517, in query
    self._affected_rows = self._read_query_result(unbuffered=unbuffered)
  File "/Users/ivanwahlrab/anaconda3/lib/python3.6/site-packages/pymysql/connections.py", line 732, in _read_query_result
    result.read()
  File "/Users/ivanwahlrab/anaconda3/lib/python3.6/site-packages/pymysql/connections.py", line 1075, in read
    first_packet = self.connection._read_packet()
  File "/Users/ivanwahlrab/anaconda3/lib/python3.6/site-packages/pymysql/connections.py", line 684, in _read_packet
    packet.check_error()
  File "/Users/ivanwahlrab/anaconda3/lib/python3.6/site-packages/pymysql/protocol.py", line 220, in check_error
    err.raise_mysql_exception(self._data)
  File "/Users/ivanwahlrab/anaconda3/lib/python3.6/site-packages/pymysql/err.py", line 109, in raise_mysql_exception
    raise errorclass(errno, errval)
pymysql.err.IntegrityError: (1062, "Duplicate entry 'SMITHFIELD NORTH' for key 'PRIMARY'")

Details of error at 2019-02-18 20:14:
 
Traceback (most recent call last):
  File "/Users/ivanwahlrab/Documents/Semester_2_19/Software_Engineering_30830/Project/dublinBikes/softwareEngineering/dublinBikes/staticDataScraper.py", line 72, in <module>
    writeData(bikesSQL)
  File "/Users/ivanwahlrab/Documents/Semester_2_19/Software_Engineering_30830/Project/dublinBikes/softwareEngineering/dublinBikes/staticDataScraper.py", line 62, in writeData
    cursorObject.execute(query)
  File "/Users/ivanwahlrab/anaconda3/lib/python3.6/site-packages/pymysql/cursors.py", line 170, in execute
    result = self._query(query)
  File "/Users/ivanwahlrab/anaconda3/lib/python3.6/site-packages/pymysql/cursors.py", line 328, in _query
    conn.query(q)
  File "/Users/ivanwahlrab/anaconda3/lib/python3.6/site-packages/pymysql/connections.py", line 517, in query
    self._affected_rows = self._read_query_result(unbuffered=unbuffered)
  File "/Users/ivanwahlrab/anaconda3/lib/python3.6/site-packages/pymysql/connections.py", line 732, in _read_query_result
    result.read()
  File "/Users/ivanwahlrab/anaconda3/lib/python3.6/site-packages/pymysql/connections.py", line 1075, in read
    first_packet = self.connection._read_packet()
  File "/Users/ivanwahlrab/anaconda3/lib/python3.6/site-packages/pymysql/connections.py", line 684, in _read_packet
    packet.check_error()
  File "/Users/ivanwahlrab/anaconda3/lib/python3.6/site-packages/pymysql/protocol.py", line 220, in check_error
    err.raise_mysql_exception(self._data)
  File "/Users/ivanwahlrab/anaconda3/lib/python3.6/site-packages/pymysql/err.py", line 109, in raise_mysql_exception
    raise errorclass(errno, errval)
pymysql.err.IntegrityError: (1062, "Duplicate entry 'SMITHFIELD NORTH' for key 'PRIMARY'")

Details of error at 2019-02-18 20:15:
 
Traceback (most recent call last):
  File "/Users/ivanwahlrab/Documents/Semester_2_19/Software_Engineering_30830/Project/dublinBikes/softwareEngineering/dublinBikes/staticDataScraper.py", line 72, in <module>
    writeData(bikesSQL)
  File "/Users/ivanwahlrab/Documents/Semester_2_19/Software_Engineering_30830/Project/dublinBikes/softwareEngineering/dublinBikes/staticDataScraper.py", line 62, in writeData
    cursorObject.execute(query)
  File "/Users/ivanwahlrab/anaconda3/lib/python3.6/site-packages/pymysql/cursors.py", line 170, in execute
    result = self._query(query)
  File "/Users/ivanwahlrab/anaconda3/lib/python3.6/site-packages/pymysql/cursors.py", line 328, in _query
    conn.query(q)
  File "/Users/ivanwahlrab/anaconda3/lib/python3.6/site-packages/pymysql/connections.py", line 517, in query
    self._affected_rows = self._read_query_result(unbuffered=unbuffered)
  File "/Users/ivanwahlrab/anaconda3/lib/python3.6/site-packages/pymysql/connections.py", line 732, in _read_query_result
    result.read()
  File "/Users/ivanwahlrab/anaconda3/lib/python3.6/site-packages/pymysql/connections.py", line 1075, in read
    first_packet = self.connection._read_packet()
  File "/Users/ivanwahlrab/anaconda3/lib/python3.6/site-packages/pymysql/connections.py", line 684, in _read_packet
    packet.check_error()
  File "/Users/ivanwahlrab/anaconda3/lib/python3.6/site-packages/pymysql/protocol.py", line 220, in check_error
    err.raise_mysql_exception(self._data)
  File "/Users/ivanwahlrab/anaconda3/lib/python3.6/site-packages/pymysql/err.py", line 109, in raise_mysql_exception
    raise errorclass(errno, errval)
pymysql.err.IntegrityError: (1062, "Duplicate entry 'SMITHFIELD NORTH' for key 'PRIMARY'")

Details of error at 2019-02-18 20:18:
 
Traceback (most recent call last):
  File "/Users/ivanwahlrab/Documents/Semester_2_19/Software_Engineering_30830/Project/dublinBikes/softwareEngineering/dublinBikes/staticDataScraper.py", line 72, in <module>
    writeData(bikesSQL)
  File "/Users/ivanwahlrab/Documents/Semester_2_19/Software_Engineering_30830/Project/dublinBikes/softwareEngineering/dublinBikes/staticDataScraper.py", line 62, in writeData
    cursorObject.execute(query)
  File "/Users/ivanwahlrab/anaconda3/lib/python3.6/site-packages/pymysql/cursors.py", line 170, in execute
    result = self._query(query)
  File "/Users/ivanwahlrab/anaconda3/lib/python3.6/site-packages/pymysql/cursors.py", line 328, in _query
    conn.query(q)
  File "/Users/ivanwahlrab/anaconda3/lib/python3.6/site-packages/pymysql/connections.py", line 517, in query
    self._affected_rows = self._read_query_result(unbuffered=unbuffered)
  File "/Users/ivanwahlrab/anaconda3/lib/python3.6/site-packages/pymysql/connections.py", line 732, in _read_query_result
    result.read()
  File "/Users/ivanwahlrab/anaconda3/lib/python3.6/site-packages/pymysql/connections.py", line 1075, in read
    first_packet = self.connection._read_packet()
  File "/Users/ivanwahlrab/anaconda3/lib/python3.6/site-packages/pymysql/connections.py", line 684, in _read_packet
    packet.check_error()
  File "/Users/ivanwahlrab/anaconda3/lib/python3.6/site-packages/pymysql/protocol.py", line 220, in check_error
    err.raise_mysql_exception(self._data)
  File "/Users/ivanwahlrab/anaconda3/lib/python3.6/site-packages/pymysql/err.py", line 109, in raise_mysql_exception
    raise errorclass(errno, errval)
pymysql.err.IntegrityError: (1062, "Duplicate entry 'SMITHFIELD NORTH' for key 'PRIMARY'")

Details of error at 2019-02-18 20:18:
 
Traceback (most recent call last):
  File "/Users/ivanwahlrab/Documents/Semester_2_19/Software_Engineering_30830/Project/dublinBikes/softwareEngineering/dublinBikes/staticDataScraper.py", line 72, in <module>
    writeData(bikesSQL)
  File "/Users/ivanwahlrab/Documents/Semester_2_19/Software_Engineering_30830/Project/dublinBikes/softwareEngineering/dublinBikes/staticDataScraper.py", line 62, in writeData
    cursorObject.execute(query)
  File "/Users/ivanwahlrab/anaconda3/lib/python3.6/site-packages/pymysql/cursors.py", line 170, in execute
    result = self._query(query)
  File "/Users/ivanwahlrab/anaconda3/lib/python3.6/site-packages/pymysql/cursors.py", line 328, in _query
    conn.query(q)
  File "/Users/ivanwahlrab/anaconda3/lib/python3.6/site-packages/pymysql/connections.py", line 517, in query
    self._affected_rows = self._read_query_result(unbuffered=unbuffered)
  File "/Users/ivanwahlrab/anaconda3/lib/python3.6/site-packages/pymysql/connections.py", line 732, in _read_query_result
    result.read()
  File "/Users/ivanwahlrab/anaconda3/lib/python3.6/site-packages/pymysql/connections.py", line 1075, in read
    first_packet = self.connection._read_packet()
  File "/Users/ivanwahlrab/anaconda3/lib/python3.6/site-packages/pymysql/connections.py", line 684, in _read_packet
    packet.check_error()
  File "/Users/ivanwahlrab/anaconda3/lib/python3.6/site-packages/pymysql/protocol.py", line 220, in check_error
    err.raise_mysql_exception(self._data)
  File "/Users/ivanwahlrab/anaconda3/lib/python3.6/site-packages/pymysql/err.py", line 109, in raise_mysql_exception
    raise errorclass(errno, errval)
pymysql.err.IntegrityError: (1062, "Duplicate entry 'SMITHFIELD NORTH' for key 'PRIMARY'")

Details of error at 2019-02-18 20:19:
 
Traceback (most recent call last):
  File "/Users/ivanwahlrab/Documents/Semester_2_19/Software_Engineering_30830/Project/dublinBikes/softwareEngineering/dublinBikes/staticDataScraper.py", line 72, in <module>
    writeData(bikesSQL)
  File "/Users/ivanwahlrab/Documents/Semester_2_19/Software_Engineering_30830/Project/dublinBikes/softwareEngineering/dublinBikes/staticDataScraper.py", line 62, in writeData
    cursorObject.execute(query)
  File "/Users/ivanwahlrab/anaconda3/lib/python3.6/site-packages/pymysql/cursors.py", line 170, in execute
    result = self._query(query)
  File "/Users/ivanwahlrab/anaconda3/lib/python3.6/site-packages/pymysql/cursors.py", line 328, in _query
    conn.query(q)
  File "/Users/ivanwahlrab/anaconda3/lib/python3.6/site-packages/pymysql/connections.py", line 517, in query
    self._affected_rows = self._read_query_result(unbuffered=unbuffered)
  File "/Users/ivanwahlrab/anaconda3/lib/python3.6/site-packages/pymysql/connections.py", line 732, in _read_query_result
    result.read()
  File "/Users/ivanwahlrab/anaconda3/lib/python3.6/site-packages/pymysql/connections.py", line 1075, in read
    first_packet = self.connection._read_packet()
  File "/Users/ivanwahlrab/anaconda3/lib/python3.6/site-packages/pymysql/connections.py", line 684, in _read_packet
    packet.check_error()
  File "/Users/ivanwahlrab/anaconda3/lib/python3.6/site-packages/pymysql/protocol.py", line 220, in check_error
    err.raise_mysql_exception(self._data)
  File "/Users/ivanwahlrab/anaconda3/lib/python3.6/site-packages/pymysql/err.py", line 109, in raise_mysql_exception
    raise errorclass(errno, errval)
pymysql.err.ProgrammingError: (1064, "You have an error in your SQL syntax; check the manual that corresponds to your MySQL server version for the right syntax to use near 'CONNELL'S)','53.357841','-6.251557','False','30')' at line 1")

Details of error at 2019-02-18 20:21:
 
Traceback (most recent call last):
  File "/Users/ivanwahlrab/Documents/Semester_2_19/Software_Engineering_30830/Project/dublinBikes/softwareEngineering/dublinBikes/staticDataScraper.py", line 72, in <module>
    writeData(bikesSQL)
  File "/Users/ivanwahlrab/Documents/Semester_2_19/Software_Engineering_30830/Project/dublinBikes/softwareEngineering/dublinBikes/staticDataScraper.py", line 62, in writeData
    cursorObject.execute(query)
  File "/Users/ivanwahlrab/anaconda3/lib/python3.6/site-packages/pymysql/cursors.py", line 170, in execute
    result = self._query(query)
  File "/Users/ivanwahlrab/anaconda3/lib/python3.6/site-packages/pymysql/cursors.py", line 328, in _query
    conn.query(q)
  File "/Users/ivanwahlrab/anaconda3/lib/python3.6/site-packages/pymysql/connections.py", line 517, in query
    self._affected_rows = self._read_query_result(unbuffered=unbuffered)
  File "/Users/ivanwahlrab/anaconda3/lib/python3.6/site-packages/pymysql/connections.py", line 732, in _read_query_result
    result.read()
  File "/Users/ivanwahlrab/anaconda3/lib/python3.6/site-packages/pymysql/connections.py", line 1075, in read
    first_packet = self.connection._read_packet()
  File "/Users/ivanwahlrab/anaconda3/lib/python3.6/site-packages/pymysql/connections.py", line 684, in _read_packet
    packet.check_error()
  File "/Users/ivanwahlrab/anaconda3/lib/python3.6/site-packages/pymysql/protocol.py", line 220, in check_error
    err.raise_mysql_exception(self._data)
  File "/Users/ivanwahlrab/anaconda3/lib/python3.6/site-packages/pymysql/err.py", line 109, in raise_mysql_exception
    raise errorclass(errno, errval)
pymysql.err.ProgrammingError: (1064, "You have an error in your SQL syntax; check the manual that corresponds to your MySQL server version for the right syntax to use near 'CONNELL'S)','53.357841','-6.251557','False','30')' at line 1")

Details of error at 2019-02-18 20:23:
 
Traceback (most recent call last):
  File "/Users/ivanwahlrab/Documents/Semester_2_19/Software_Engineering_30830/Project/dublinBikes/softwareEngineering/dublinBikes/staticDataScraper.py", line 72, in <module>
    writeData(bikesSQL)
  File "/Users/ivanwahlrab/Documents/Semester_2_19/Software_Engineering_30830/Project/dublinBikes/softwareEngineering/dublinBikes/staticDataScraper.py", line 63, in writeData
    cursorObject.execute(query)
  File "/Users/ivanwahlrab/anaconda3/lib/python3.6/site-packages/pymysql/cursors.py", line 170, in execute
    result = self._query(query)
  File "/Users/ivanwahlrab/anaconda3/lib/python3.6/site-packages/pymysql/cursors.py", line 328, in _query
    conn.query(q)
  File "/Users/ivanwahlrab/anaconda3/lib/python3.6/site-packages/pymysql/connections.py", line 517, in query
    self._affected_rows = self._read_query_result(unbuffered=unbuffered)
  File "/Users/ivanwahlrab/anaconda3/lib/python3.6/site-packages/pymysql/connections.py", line 732, in _read_query_result
    result.read()
  File "/Users/ivanwahlrab/anaconda3/lib/python3.6/site-packages/pymysql/connections.py", line 1075, in read
    first_packet = self.connection._read_packet()
  File "/Users/ivanwahlrab/anaconda3/lib/python3.6/site-packages/pymysql/connections.py", line 684, in _read_packet
    packet.check_error()
  File "/Users/ivanwahlrab/anaconda3/lib/python3.6/site-packages/pymysql/protocol.py", line 220, in check_error
    err.raise_mysql_exception(self._data)
  File "/Users/ivanwahlrab/anaconda3/lib/python3.6/site-packages/pymysql/err.py", line 109, in raise_mysql_exception
    raise errorclass(errno, errval)
pymysql.err.IntegrityError: (1062, "Duplicate entry 'SMITHFIELD NORTH' for key 'PRIMARY'")

Details of error at 2019-02-18 20:23:
 
Traceback (most recent call last):
  File "/Users/ivanwahlrab/Documents/Semester_2_19/Software_Engineering_30830/Project/dublinBikes/softwareEngineering/dublinBikes/staticDataScraper.py", line 72, in <module>
    writeData(bikesSQL)
  File "/Users/ivanwahlrab/Documents/Semester_2_19/Software_Engineering_30830/Project/dublinBikes/softwareEngineering/dublinBikes/staticDataScraper.py", line 63, in writeData
    cursorObject.execute(query)
  File "/Users/ivanwahlrab/anaconda3/lib/python3.6/site-packages/pymysql/cursors.py", line 170, in execute
    result = self._query(query)
  File "/Users/ivanwahlrab/anaconda3/lib/python3.6/site-packages/pymysql/cursors.py", line 328, in _query
    conn.query(q)
  File "/Users/ivanwahlrab/anaconda3/lib/python3.6/site-packages/pymysql/connections.py", line 517, in query
    self._affected_rows = self._read_query_result(unbuffered=unbuffered)
  File "/Users/ivanwahlrab/anaconda3/lib/python3.6/site-packages/pymysql/connections.py", line 732, in _read_query_result
    result.read()
  File "/Users/ivanwahlrab/anaconda3/lib/python3.6/site-packages/pymysql/connections.py", line 1075, in read
    first_packet = self.connection._read_packet()
  File "/Users/ivanwahlrab/anaconda3/lib/python3.6/site-packages/pymysql/connections.py", line 684, in _read_packet
    packet.check_error()
  File "/Users/ivanwahlrab/anaconda3/lib/python3.6/site-packages/pymysql/protocol.py", line 220, in check_error
    err.raise_mysql_exception(self._data)
  File "/Users/ivanwahlrab/anaconda3/lib/python3.6/site-packages/pymysql/err.py", line 109, in raise_mysql_exception
    raise errorclass(errno, errval)
pymysql.err.ProgrammingError: (1064, "You have an error in your SQL syntax; check the manual that corresponds to your MySQL server version for the right syntax to use near 'CONNELL'S)','53.357841','-6.251557','False','30')' at line 1")

Details of error at 2019-02-18 20:27:
 
Traceback (most recent call last):
  File "/Users/ivanwahlrab/Documents/Semester_2_19/Software_Engineering_30830/Project/dublinBikes/softwareEngineering/dublinBikes/staticDataScraper.py", line 72, in <module>
    writeData(bikesSQL)
  File "/Users/ivanwahlrab/Documents/Semester_2_19/Software_Engineering_30830/Project/dublinBikes/softwareEngineering/dublinBikes/staticDataScraper.py", line 63, in writeData
    cursorObject.execute(query)
  File "/Users/ivanwahlrab/anaconda3/lib/python3.6/site-packages/pymysql/cursors.py", line 170, in execute
    result = self._query(query)
  File "/Users/ivanwahlrab/anaconda3/lib/python3.6/site-packages/pymysql/cursors.py", line 328, in _query
    conn.query(q)
  File "/Users/ivanwahlrab/anaconda3/lib/python3.6/site-packages/pymysql/connections.py", line 517, in query
    self._affected_rows = self._read_query_result(unbuffered=unbuffered)
  File "/Users/ivanwahlrab/anaconda3/lib/python3.6/site-packages/pymysql/connections.py", line 732, in _read_query_result
    result.read()
  File "/Users/ivanwahlrab/anaconda3/lib/python3.6/site-packages/pymysql/connections.py", line 1075, in read
    first_packet = self.connection._read_packet()
  File "/Users/ivanwahlrab/anaconda3/lib/python3.6/site-packages/pymysql/connections.py", line 684, in _read_packet
    packet.check_error()
  File "/Users/ivanwahlrab/anaconda3/lib/python3.6/site-packages/pymysql/protocol.py", line 220, in check_error
    err.raise_mysql_exception(self._data)
  File "/Users/ivanwahlrab/anaconda3/lib/python3.6/site-packages/pymysql/err.py", line 109, in raise_mysql_exception
    raise errorclass(errno, errval)
pymysql.err.IntegrityError: (1062, "Duplicate entry 'SMITHFIELD NORTH' for key 'PRIMARY'")

Details of error at 2019-02-18 20:27:
 
Traceback (most recent call last):
  File "/Users/ivanwahlrab/Documents/Semester_2_19/Software_Engineering_30830/Project/dublinBikes/softwareEngineering/dublinBikes/staticDataScraper.py", line 72, in <module>
    writeData(bikesSQL)
  File "/Users/ivanwahlrab/Documents/Semester_2_19/Software_Engineering_30830/Project/dublinBikes/softwareEngineering/dublinBikes/staticDataScraper.py", line 59, in writeData
    conn = pymysql.connect(host, user=user,port=port, passwd=password, db=dbname)
  File "/Users/ivanwahlrab/anaconda3/lib/python3.6/site-packages/pymysql/__init__.py", line 94, in Connect
    return Connection(*args, **kwargs)
  File "/Users/ivanwahlrab/anaconda3/lib/python3.6/site-packages/pymysql/connections.py", line 325, in __init__
    self.connect()
  File "/Users/ivanwahlrab/anaconda3/lib/python3.6/site-packages/pymysql/connections.py", line 598, in connect
    self._get_server_information()
  File "/Users/ivanwahlrab/anaconda3/lib/python3.6/site-packages/pymysql/connections.py", line 975, in _get_server_information
    packet = self._read_packet()
  File "/Users/ivanwahlrab/anaconda3/lib/python3.6/site-packages/pymysql/connections.py", line 657, in _read_packet
    packet_header = self._read_bytes(4)
  File "/Users/ivanwahlrab/anaconda3/lib/python3.6/site-packages/pymysql/connections.py", line 691, in _read_bytes
    data = self._rfile.read(num_bytes)
  File "/Users/ivanwahlrab/anaconda3/lib/python3.6/socket.py", line 586, in readinto
    return self._sock.recv_into(b)
KeyboardInterrupt

Details of error at 2019-02-18 20:32:
 
Traceback (most recent call last):
  File "/Users/ivanwahlrab/Documents/Semester_2_19/Software_Engineering_30830/Project/dublinBikes/softwareEngineering/dublinBikes/combinedScraper.py", line 154, in <module>
    for i in range(0,len(dbds)):
NameError: name 'dbds' is not defined

Details of error at 2019-02-18 20:34:
 
Traceback (most recent call last):
  File "/Users/ivanwahlrab/Documents/Semester_2_19/Software_Engineering_30830/Project/dublinBikes/softwareEngineering/dublinBikes/combinedScraper.py", line 154, in <module>
    for i in range(0,len(dbds)):
NameError: name 'dbds' is not defined

